Workbook

Sheet Start Here
B2: SunSystems Parts Desk
B3: Someone needs a part. You know where to get it. This workbook turns that into money, every time.
B5: THE SYSTEM (input → process → output)
B6: Input | C6: A request comes in: part number / spec, quantity, needed-by date. Log it in RFQ Log the same day.
B7: Process | C7: Find it, get the supplier's price + shipping, let the sheet compute the quote, send it, collect payment, place the order.
B8: Output | C8: Profit. Dashboard shows what you've made, what's in play, and who you owe a follow-up.
B9: Your edge | C9: You know where parts live. The customer is paying for your knowledge + time + risk, not for the part. Price accordingly.
B11: THE 7 STEPS FOR EVERY REQUEST
B12: 1. Intake (New) | C12: Get EXACT part #, revision, spec, qty, needed-by date, ship-to. A photo of the nameplate/old part beats a description. Log it.
B13: 2. Source (Sourcing) | C13: Call 1–3 suppliers. Write down unit cost, shipping, lead time. Pick one. Enter cost in RFQ Log.
B14: 3. Quote (Quoted) | C14: Sheet computes Suggested Quote. Override in 'Your Quote' if you know the market. Send a written quote (template in the guide) valid for 7 days.
B15: 4. Close (Won) | C15: Customer says yes IN WRITING (email/text is fine). Collect payment or deposit BEFORE you buy.
B16: 5. Order (Ordered) | C16: Buy from supplier. Ship direct to the customer when possible (drop-ship) so you never touch inventory.
B17: 6. Deliver (Shipped) | C17: Send tracking to customer. Confirm it arrived and is the right part.
B18: 7. Get paid (Paid) | C18: Collect the balance. Enter Date Paid. Profit now shows on the Dashboard.
B20: NON-NEGOTIABLE RULES
B21: Money first | C21: Never pay a supplier with your own money before the customer has paid (or paid a deposit that covers your cost). This one rule prevents most losses.
B22: In writing | C22: Every quote, every yes, every spec confirmation: text or email. 'Yes, part #XYZ rev C qty 4 at $X' is your contract.
B23: Exact match | C23: Wrong part = you eat the return shipping + restocking fee. Confirm part #, revision, voltage, thread, material — whatever matters — before ordering.
B24: Protect the source | C24: Don't name your supplier to the customer. Drop-ship with a neutral packing slip when possible. Your contacts are the business.
B25: Mirror the returns policy | C25: Your return terms can't be better than your supplier's. If they charge 20% restocking, so do you.
B26: Min profit floor | C26: Small orders still cost you an hour. Settings tab enforces a minimum profit per deal (default $50).
B28: HOW TO READ THIS WORKBOOK
B29: Yellow cell, blue text | C29: INPUT — you type here.
B30: Black text | C30: FORMULA — don't type over it. It's computed.
B31: Green text | C31: Pulled from another tab.
B32: Rows marked (example) | C32: Sample data so you can see how it works. Delete or overwrite them when you start.
B34: THE TABS
B35: Settings | C35: Your pricing rules: markup tiers by order size, minimum profit, card-fee %, rounding, follow-up days. Change once, every quote follows.
B36: Quote Calc | C36: Scratchpad for building one multi-line quote. Gives suggested price, price at a target margin, per-unit customer prices.
B37: RFQ Log | C37: The core. One row per request. Track it from New to Paid. Profit, margin, and follow-up dates compute automatically.
B38: Suppliers | C38: Your black book. Who carries what, lead times, terms, how reliable they are, how many deals you've done with them.
B39: Customers | C39: Who asks, how they found you, what they've bought, what they're worth to you.
B40: Dashboard | C40: Profit collected, profit in play, win rate, overdue follow-ups, profit by month.
B42: MARKUP vs MARGIN (the engineer's footnote)
B43: Markup | C43: Profit ÷ Cost. Cost $100, sell $125 → 25% markup.
B44: Margin | C44: Profit ÷ Price. Same deal → $25 ÷ $125 = 20% margin.
B45: Conversion | C45: margin = markup ÷ (1 + markup). markup = margin ÷ (1 − margin). See the table on the Quote Calc tab.
B46: Card fees | C46: If the customer pays by card you lose ~3% of the PRICE. The sheet grosses the quote up so that fee comes out of their price, not your profit.

Sheet Dashboard
A1: Dashboard
A2: ="As of "&TEXT(TODAY(),"mmm d, yyyy") -> As of Oct 14, 2026
A3: MONEY | D3: PIPELINE BY STATUS
A4: Profit collected (Paid) | B4: =SUMIFS('RFQ Log'!$P$5:$P$304,'RFQ Log'!$R$5:$R$304,"Paid") -> 52.05 | D4: Status | E4: Count | F4: Price sent ($)
A5: Revenue collected (Paid) | B5: =SUMIFS('RFQ Log'!$O$5:$O$304,'RFQ Log'!$R$5:$R$304,"Paid") -> 125 | D5: New | E5: =COUNTIF('RFQ Log'!$R$5:$R$304,D5) -> 0 | F5: =SUMIFS('RFQ Log'!$O$5:$O$304,'RFQ Log'!$R$5:$R$304,D5) -> 0
A6: Average margin on paid deals | B6: =IF(B5=0,0,B4/B5) -> 0.4164 | D6: Sourcing | E6: =COUNTIF('RFQ Log'!$R$5:$R$304,D6) -> 0 | F6: =SUMIFS('RFQ Log'!$O$5:$O$304,'RFQ Log'!$R$5:$R$304,D6) -> 0
A7: Profit in play (Won/Ordered/Shipped) | B7: =SUMIFS('RFQ Log'!$P$5:$P$304,'RFQ Log'!$R$5:$R$304,"Won")+SUMIFS('RFQ Log'!$P$5:$P$304,'RFQ Log'!$R$5:$R$304,"Ordered")+SUMIFS('RFQ Log'!$P$5:$P$304,'RFQ Log'!$R$5:$R$304,"Shipped") -> 375.5 | D7: Quoted | E7: =COUNTIF('RFQ Log'!$R$5:$R$304,D7) -> 1 | F7: =SUMIFS('RFQ Log'!$O$5:$O$304,'RFQ Log'!$R$5:$R$304,D7) -> 230
A8: Profit on the table (Quoted) | B8: =SUMIFS('RFQ Log'!$P$5:$P$304,'RFQ Log'!$R$5:$R$304,"Quoted") -> 60.1 | D8: Won | E8: =COUNTIF('RFQ Log'!$R$5:$R$304,D8) -> 0 | F8: =SUMIFS('RFQ Log'!$O$5:$O$304,'RFQ Log'!$R$5:$R$304,D8) -> 0
A9: Profit this month (by Date Paid) | B9: =SUMIFS('RFQ Log'!$P$5:$P$304,'RFQ Log'!$R$5:$R$304,"Paid",'RFQ Log'!$U$5:$U$304,">="&DATE(YEAR(TODAY()),MONTH(TODAY()),1),'RFQ Log'!$U$5:$U$304,"<"&EDATE(DATE(YEAR(TODAY()),MONTH(TODAY()),1),1)) -> 0 | D9: Ordered | E9: =COUNTIF('RFQ Log'!$R$5:$R$304,D9) -> 0 | F9: =SUMIFS('RFQ Log'!$O$5:$O$304,'RFQ Log'!$R$5:$R$304,D9) -> 0
D10: Shipped | E10: =COUNTIF('RFQ Log'!$R$5:$R$304,D10) -> 1 | F10: =SUMIFS('RFQ Log'!$O$5:$O$304,'RFQ Log'!$R$5:$R$304,D10) -> 1650
A11: ACTIVITY | D11: Paid | E11: =COUNTIF('RFQ Log'!$R$5:$R$304,D11) -> 1 | F11: =SUMIFS('RFQ Log'!$O$5:$O$304,'RFQ Log'!$R$5:$R$304,D11) -> 125
A12: Total requests logged | B12: =COUNT('RFQ Log'!$B$5:$B$304) -> 3 | D12: Lost | E12: =COUNTIF('RFQ Log'!$R$5:$R$304,D12) -> 0 | F12: =SUMIFS('RFQ Log'!$O$5:$O$304,'RFQ Log'!$R$5:$R$304,D12) -> 0
A13: Win rate (won ÷ decided) | B13: =IFERROR((COUNTIF('RFQ Log'!$R$5:$R$304,"Won")+COUNTIF('RFQ Log'!$R$5:$R$304,"Ordered")+COUNTIF('RFQ Log'!$R$5:$R$304,"Shipped")+COUNTIF('RFQ Log'!$R$5:$R$304,"Paid"))/((COUNTIF('RFQ Log'!$R$5:$R$304,"Won")+COUNTIF('RFQ Log'!$R$5:$R$304,"Ordered")+COUNTIF('RFQ Log'!$R$5:$R$304,"Shipped")+COUNTIF('RFQ Log'!$R$5:$R$304,"Paid"))+COUNTIF('RFQ Log'!$R$5:$R$304,"Lost")),0) -> 1
A14: Open requests (New/Sourcing/Quoted) | B14: =COUNTIF('RFQ Log'!$R$5:$R$304,"New")+COUNTIF('RFQ Log'!$R$5:$R$304,"Sourcing")+COUNTIF('RFQ Log'!$R$5:$R$304,"Quoted") -> 1
A15: FOLLOW-UPS DUE NOW | B15: =COUNTIFS('RFQ Log'!$S$5:$S$304,"<="&TODAY(),'RFQ Log'!$R$5:$R$304,"New")+COUNTIFS('RFQ Log'!$S$5:$S$304,"<="&TODAY(),'RFQ Log'!$R$5:$R$304,"Sourcing")+COUNTIFS('RFQ Log'!$S$5:$S$304,"<="&TODAY(),'RFQ Log'!$R$5:$R$304,"Quoted") -> 1
A16: Shipped, waiting on payment | B16: =COUNTIF('RFQ Log'!$R$5:$R$304,"Shipped") -> 1
A19: PROFIT BY MONTH (this year, by Date Paid)
A20: Month | B20: Profit ($)
A21: =DATE(YEAR(TODAY()),1,1) -> 46023 | B21: =SUMIFS('RFQ Log'!$P$5:$P$304,'RFQ Log'!$R$5:$R$304,"Paid",'RFQ Log'!$U$5:$U$304,">="&A21,'RFQ Log'!$U$5:$U$304,"<"&EDATE(A21,1)) -> 0
A22: =DATE(YEAR(TODAY()),2,1) -> 46054 | B22: =SUMIFS('RFQ Log'!$P$5:$P$304,'RFQ Log'!$R$5:$R$304,"Paid",'RFQ Log'!$U$5:$U$304,">="&A22,'RFQ Log'!$U$5:$U$304,"<"&EDATE(A22,1)) -> 0
A23: =DATE(YEAR(TODAY()),3,1) -> 46082 | B23: =SUMIFS('RFQ Log'!$P$5:$P$304,'RFQ Log'!$R$5:$R$304,"Paid",'RFQ Log'!$U$5:$U$304,">="&A23,'RFQ Log'!$U$5:$U$304,"<"&EDATE(A23,1)) -> 0
A24: =DATE(YEAR(TODAY()),4,1) -> 46113 | B24: =SUMIFS('RFQ Log'!$P$5:$P$304,'RFQ Log'!$R$5:$R$304,"Paid",'RFQ Log'!$U$5:$U$304,">="&A24,'RFQ Log'!$U$5:$U$304,"<"&EDATE(A24,1)) -> 0
A25: =DATE(YEAR(TODAY()),5,1) -> 46143 | B25: =SUMIFS('RFQ Log'!$P$5:$P$304,'RFQ Log'!$R$5:$R$304,"Paid",'RFQ Log'!$U$5:$U$304,">="&A25,'RFQ Log'!$U$5:$U$304,"<"&EDATE(A25,1)) -> 0
A26: =DATE(YEAR(TODAY()),6,1) -> 46174 | B26: =SUMIFS('RFQ Log'!$P$5:$P$304,'RFQ Log'!$R$5:$R$304,"Paid",'RFQ Log'!$U$5:$U$304,">="&A26,'RFQ Log'!$U$5:$U$304,"<"&EDATE(A26,1)) -> 0
A27: =DATE(YEAR(TODAY()),7,1) -> 46204 | B27: =SUMIFS('RFQ Log'!$P$5:$P$304,'RFQ Log'!$R$5:$R$304,"Paid",'RFQ Log'!$U$5:$U$304,">="&A27,'RFQ Log'!$U$5:$U$304,"<"&EDATE(A27,1)) -> 0
A28: =DATE(YEAR(TODAY()),8,1) -> 46235 | B28: =SUMIFS('RFQ Log'!$P$5:$P$304,'RFQ Log'!$R$5:$R$304,"Paid",'RFQ Log'!$U$5:$U$304,">="&A28,'RFQ Log'!$U$5:$U$304,"<"&EDATE(A28,1)) -> 0
A29: =DATE(YEAR(TODAY()),9,1) -> 46266 | B29: =SUMIFS('RFQ Log'!$P$5:$P$304,'RFQ Log'!$R$5:$R$304,"Paid",'RFQ Log'!$U$5:$U$304,">="&A29,'RFQ Log'!$U$5:$U$304,"<"&EDATE(A29,1)) -> 52.05
A30: =DATE(YEAR(TODAY()),10,1) -> 46296 | B30: =SUMIFS('RFQ Log'!$P$5:$P$304,'RFQ Log'!$R$5:$R$304,"Paid",'RFQ Log'!$U$5:$U$304,">="&A30,'RFQ Log'!$U$5:$U$304,"<"&EDATE(A30,1)) -> 0
A31: =DATE(YEAR(TODAY()),11,1) -> 46327 | B31: =SUMIFS('RFQ Log'!$P$5:$P$304,'RFQ Log'!$R$5:$R$304,"Paid",'RFQ Log'!$U$5:$U$304,">="&A31,'RFQ Log'!$U$5:$U$304,"<"&EDATE(A31,1)) -> 0
A32: =DATE(YEAR(TODAY()),12,1) -> 46357 | B32: =SUMIFS('RFQ Log'!$P$5:$P$304,'RFQ Log'!$R$5:$R$304,"Paid",'RFQ Log'!$U$5:$U$304,">="&A32,'RFQ Log'!$U$5:$U$304,"<"&EDATE(A32,1)) -> 0

Sheet Settings
A1: Settings — your pricing rules
A2: Change the yellow cells. Every formula in the workbook reads from here.
A3: Setting | B3: Value | C3: What it does
A4: Payment processing fee % | B4: 0.03 | C4: Card/online invoice fee taken from the price (Stripe/Square/QuickBooks ≈ 2.9–3.5%). Set 0 if paid by check/ACH/cash. Assumption — check your processor.
A5: Minimum profit per deal ($) | B5: 50 | C5: Floor so tiny orders are still worth your time. Assumption — set to what an hour of your time is worth.
A6: Round quotes UP to nearest ($) | B6: 5 | C6: Clean numbers look professional and add a little cushion. Use 1 for no rounding.
A7: Quote valid for (days) | B7: 7 | C7: Put this on every quote. Supplier prices move; don't get stuck honoring an old one.
A8: Follow up after (days) | B8: 3 | C8: RFQ Log flags the follow-up date this many days after a request comes in.
A9: Deposit required before ordering % | B9: 0.5 | C9: Minimum up-front payment before you buy. Must at least cover your landed cost. 100% for new customers is reasonable.
A12: Markup tiers — bigger orders, smaller %
A13: Landed cost from ($) | B13: Markup % | C13: Why
A14: 0 | B14: 0.35 | C14: Small one-off parts: your time is most of the value.
A15: 500 | B15: 0.25 | C15: Typical repair/replacement order.
A16: 2000 | B16: 0.18 | C16: Mid-size: customer is more likely to shop around.
A17: 10000 | B17: 0.12 | C17: Large: still real dollars, keep it competitive.
A18: 50000 | B18: 0.08 | C18: Very large: negotiate case by case; this is the floor.
A20: Tiers are starting-point assumptions, not market data. Keep the 'from' column sorted smallest → largest, starting at 0. If you know the going rate for a part, override the price in RFQ Log.
A23: Status list (used by dropdowns)
A24: New | B24: Request logged
A25: Sourcing | B25: Hunting for supplier/price
A26: Quoted | B26: Quote sent, waiting on customer
A27: Won | B27: Customer said yes
A28: Ordered | B28: You placed the supplier order
A29: Shipped | B29: On its way to customer
A30: Paid | B30: Customer paid in full — DONE
A31: Lost | B31: Customer passed / no source

Sheet Quote Calc
A1: Quote Calculator — build one quote
A2: Enter supplier costs in yellow. The sheet tells you what to charge. Copy the green 'Customer price' column into your quote.
A4: Customer | B4: Acme Fabrication (example)
A5: Quote # | B5: Q-001
A6: Date | B6: 46309
A7: Valid until | B7: =B6+Settings!$B$7 -> 46316
A9: Part # / Spec | B9: Description | C9: Qty | D9: Supplier unit cost | E9: Line cost | F9: Customer unit price | G9: Customer line total
A10: 6205-2RS | B10: Sealed ball bearing 25x52x15 (example) | C10: 8 | D10: 6.4 | E10: =IF(OR(C10="",D10=""),"",C10*D10) -> 51.2 | F10: =IF(OR(E10="",$E$20=0),"",ROUND(E10/$E$20*$E$34/C10,2)) -> 9.8 | G10: =IF(F10="","",F10*C10) -> 78.4
A11: SC-25-150 | B11: Pneumatic cylinder 25mm bore x 150 stroke (example) | C11: 2 | D11: 74 | E11: =IF(OR(C11="",D11=""),"",C11*D11) -> 148 | F11: =IF(OR(E11="",$E$20=0),"",ROUND(E11/$E$20*$E$34/C11,2)) -> 113.3 | G11: =IF(F11="","",F11*C11) -> 226.6
E12: =IF(OR(C12="",D12=""),"",C12*D12) | F12: =IF(OR(E12="",$E$20=0),"",ROUND(E12/$E$20*$E$34/C12,2)) | G12: =IF(F12="","",F12*C12)
E13: =IF(OR(C13="",D13=""),"",C13*D13) | F13: =IF(OR(E13="",$E$20=0),"",ROUND(E13/$E$20*$E$34/C13,2)) | G13: =IF(F13="","",F13*C13)
E14: =IF(OR(C14="",D14=""),"",C14*D14) | F14: =IF(OR(E14="",$E$20=0),"",ROUND(E14/$E$20*$E$34/C14,2)) | G14: =IF(F14="","",F14*C14)
E15: =IF(OR(C15="",D15=""),"",C15*D15) | F15: =IF(OR(E15="",$E$20=0),"",ROUND(E15/$E$20*$E$34/C15,2)) | G15: =IF(F15="","",F15*C15)
E16: =IF(OR(C16="",D16=""),"",C16*D16) | F16: =IF(OR(E16="",$E$20=0),"",ROUND(E16/$E$20*$E$34/C16,2)) | G16: =IF(F16="","",F16*C16)
E17: =IF(OR(C17="",D17=""),"",C17*D17) | F17: =IF(OR(E17="",$E$20=0),"",ROUND(E17/$E$20*$E$34/C17,2)) | G17: =IF(F17="","",F17*C17)
E18: =IF(OR(C18="",D18=""),"",C18*D18) | F18: =IF(OR(E18="",$E$20=0),"",ROUND(E18/$E$20*$E$34/C18,2)) | G18: =IF(F18="","",F18*C18)
E19: =IF(OR(C19="",D19=""),"",C19*D19) | F19: =IF(OR(E19="",$E$20=0),"",ROUND(E19/$E$20*$E$34/C19,2)) | G19: =IF(F19="","",F19*C19)
D20: Parts subtotal | E20: =SUM(E10:E19) -> 199.2
D21: Inbound shipping (supplier → you) | E21: 0 | F21: 0 if drop-shipped
D22: Outbound shipping (→ customer) | E22: 18 | F22: example
D23: Other costs (fees, cert, packaging) | E23: 0
D24: LANDED COST | E24: =SUM(E20:E23) -> 217.2
D26: Tier markup (from Settings) | E26: =IF(E24=0,0,INDEX(Settings!$B$14:$B$18,MATCH(E24,Settings!$A$14:$A$18,1))) -> 0.35
D27: Suggested quote | E27: =IF(E24=0,0,CEILING(MAX(E24*(1+E26),E24+Settings!$B$5)/(1-Settings!$B$4),Settings!$B$6)) -> 305 | F27: tier markup, min-profit floor, card fee covered, rounded up
D29: OR: target margin % | E29: 0.25 | F29: what % of the price you want to keep
D30: Price at target margin | E30: =IF(OR(E24=0,1-Settings!$B$4-E29<=0),0,CEILING(E24/(1-Settings!$B$4-E29),Settings!$B$6)) -> 305 | F30: price = landed ÷ (1 − fee% − margin%)
D32: Which price? (1 = suggested, 2 = target margin, 3 = my own) | E32: 1
D33: My own price (if 3) | E33: 0 | F33: only used when 'Which price' = 3
D34: PRICE TO CUSTOMER | E34: =CHOOSE(E32,E27,E30,E33) -> 305
D35: Card / processing fee | E35: =E34*Settings!$B$4 -> 9.15
D36: YOUR PROFIT | E36: =E34-E35-E24 -> 78.65
D37: Margin (profit ÷ price) | E37: =IF(E34=0,0,E36/E34) -> 0.25786885
D38: Markup (profit ÷ landed cost) | E38: =IF(E24=0,0,E36/E24) -> 0.36210866
D39: Deposit to collect before ordering | E39: =MAX(E24,CEILING(E34*Settings!$B$9,1)) -> 217.2 | F39: at least your landed cost
A42: Markup ↔ Margin cheat sheet
A43: Markup | B43: → Margin | C43: Margin | D43: → Markup
A44: 0.1 | B44: =A44/(1+A44) -> 0.090909091 | C44: 0.1 | D44: =IF(C44>=1,0,C44/(1-C44)) -> 0.11111111
A45: 0.15 | B45: =A45/(1+A45) -> 0.13043478 | C45: 0.15 | D45: =IF(C45>=1,0,C45/(1-C45)) -> 0.17647059
A46: 0.2 | B46: =A46/(1+A46) -> 0.16666667 | C46: 0.2 | D46: =IF(C46>=1,0,C46/(1-C46)) -> 0.25
A47: 0.25 | B47: =A47/(1+A47) -> 0.2 | C47: 0.25 | D47: =IF(C47>=1,0,C47/(1-C47)) -> 0.33333333
...

Sheet RFQ Log
A1: RFQ Log — every request, New → Paid
A2: Type in yellow columns only. Leave 'Your Quote' blank to use the Suggested Quote. Fill 'Date Paid' when the money lands — that's what the Dashboard counts.
A4: ID | B4: Date In | C4: Customer | D4: Part # / Spec | E4: Description | F4: Qty | G4: Needed By | H4: Supplier | I4: Unit Cost ($) | J4: Shipping + Fees ($) | K4: Landed Cost ($) | L4: Tier Markup | M4: Suggested Quote ($) | N4: Your Quote ($) | O4: Price Sent ($) | P4: Est. Profit ($) | Q4: Margin | R4: Status | S4: Follow Up On | T4: Days Open | U4: Date Paid | V4: Notes
A5: =IF(B5="","","Q-"&TEXT(ROW()-4,"000")) -> Q-001 | B5: 46269 | C5: Acme Fabrication (example) | D5: 6205-2RS | E5: Sealed ball bearing (example) | F5: 8 | G5: 46279 | H5: Midwest Bearing Supply (example) | I5: 6.4 | J5: 18 | K5: =IF(OR(F5="",I5=""),"",F5*I5+N(J5)) -> 69.2 | L5: =IF(K5="","",INDEX(Settings!$B$14:$B$18,MATCH(K5,Settings!$A$14:$A$18,1))) -> 0.35 | M5: =IF(K5="","",CEILING(MAX(K5*(1+L5),K5+Settings!$B$5)/(1-Settings!$B$4),Settings!$B$6)) -> 125 | O5: =IF(K5="","",IF(N5="",M5,N5)) -> 125 | P5: =IF(O5="","",O5*(1-Settings!$B$4)-K5) -> 52.05 | Q5: =IF(OR(O5="",O5=0),"",P5/O5) -> 0.4164 | R5: Paid | S5: =IF(OR(B5="",R5="Paid",R5="Lost",R5="Shipped"),"",B5+Settings!$B$8) | T5: =IF(OR(B5="",R5="Paid",R5="Lost"),"",TODAY()-B5) | U5: 46281 | V5: Repeat buyer — ask about monthly stock
A6: =IF(B6="","","Q-"&TEXT(ROW()-4,"000")) -> Q-002 | B6: 46297 | C6: Lakeside Machine Shop (example) | D6: VFD-7.5HP-480V | E6: Variable frequency drive (example) | F6: 1 | G6: 46314 | H6: Great Lakes Industrial (example) | I6: 1180 | J6: 45 | K6: =IF(OR(F6="",I6=""),"",F6*I6+N(J6)) -> 1225 | L6: =IF(K6="","",INDEX(Settings!$B$14:$B$18,MATCH(K6,Settings!$A$14:$A$18,1))) -> 0.25 | M6: =IF(K6="","",CEILING(MAX(K6*(1+L6),K6+Settings!$B$5)/(1-Settings!$B$4),Settings!$B$6)) -> 1580 | N6: 1650 | O6: =IF(K6="","",IF(N6="",M6,N6)) -> 1650 | P6: =IF(O6="","",O6*(1-Settings!$B$4)-K6) -> 375.5 | Q6: =IF(OR(O6="",O6=0),"",P6/O6) -> 0.22757576 | R6: Shipped | S6: =IF(OR(B6="",R6="Paid",R6="Lost",R6="Shipped"),"",B6+Settings!$B$8) | T6: =IF(OR(B6="",R6="Paid",R6="Lost"),"",TODAY()-B6) -> 12 | V6: Customer quoted $1,900 elsewhere; priced under it
A7: =IF(B7="","","Q-"&TEXT(ROW()-4,"000")) -> Q-003 | B7: 46305 | C7: Acme Fabrication (example) | D7: SC-25-150 | E7: Pneumatic cylinder (example) | F7: 2 | G7: 46323 | H7: Midwest Bearing Supply (example) | I7: 74 | J7: 15 | K7: =IF(OR(F7="",I7=""),"",F7*I7+N(J7)) -> 163 | L7: =IF(K7="","",INDEX(Settings!$B$14:$B$18,MATCH(K7,Settings!$A$14:$A$18,1))) -> 0.35 | M7: =IF(K7="","",CEILING(MAX(K7*(1+L7),K7+Settings!$B$5)/(1-Settings!$B$4),Settings!$B$6)) -> 230 | O7: =IF(K7="","",IF(N7="",M7,N7)) -> 230 | P7: =IF(O7="","",O7*(1-Settings!$B$4)-K7) -> 60.1 | Q7: =IF(OR(O7="",O7=0),"",P7/O7) -> 0.26130435 | R7: Quoted | S7: =IF(OR(B7="",R7="Paid",R7="Lost",R7="Shipped"),"",B7+Settings!$B$8) -> 46308 | T7: =IF(OR(B7="",R7="Paid",R7="Lost"),"",TODAY()-B7) -> 4 | V7: Waiting on PO
A8: =IF(B8="","","Q-"&TEXT(ROW()-4,"000")) | K8: =IF(OR(F8="",I8=""),"",F8*I8+N(J8)) | L8: =IF(K8="","",INDEX(Settings!$B$14:$B$18,MATCH(K8,Settings!$A$14:$A$18,1))) | M8: =IF(K8="","",CEILING(MAX(K8*(1+L8),K8+Settings!$B$5)/(1-Settings!$B$4),Settings!$B$6)) | O8: =IF(K8="","",IF(N8="",M8,N8)) | P8: =IF(O8="","",O8*(1-Settings!$B$4)-K8) | Q8: =IF(OR(O8="",O8=0),"",P8/O8) | S8: =IF(OR(B8="",R8="Paid",R8="Lost",R8="Shipped"),"",B8+Settings!$B$8) | T8: =IF(OR(B8="",R8="Paid",R8="Lost"),"",TODAY()-B8)
A9: =IF(B9="","","Q-"&TEXT(ROW()-4,"000")) | K9: =IF(OR(F9="",I9=""),"",F9*I9+N(J9)) | L9: =IF(K9="","",INDEX(Settings!$B$14:$B$18,MATCH(K9,Settings!$A$14:$A$18,1))) | M9: =IF(K9="","",CEILING(MAX(K9*(1+L9),K9+Settings!$B$5)/(1-Settings!$B$4),Settings!$B$6)) | O9: =IF(K9="","",IF(N9="",M9,N9)) | P9: =IF(O9="","",O9*(1-Settings!$B$4)-K9) | Q9: =IF(OR(O9="",O9=0),"",P9/O9) | S9: =IF(OR(B9="",R9="Paid",R9="Lost",R9="Shipped"),"",B9+Settings!$B$8) | T9: =IF(OR(B9="",R9="Paid",R9="Lost"),"",TODAY()-B9)
A10: =IF(B10="","","Q-"&TEXT(ROW()-4,"000")) | K10: =IF(OR(F10="",I10=""),"",F10*I10+N(J10)) | L10: =IF(K10="","",INDEX(Settings!$B$14:$B$18,MATCH(K10,Settings!$A$14:$A$18,1))) | M10: =IF(K10="","",CEILING(MAX(K10*(1+L10),K10+Settings!$B$5)/(1-Settings!$B$4),Settings!$B$6)) | O10: =IF(K10="","",IF(N10="",M10,N10)) | P10: =IF(O10="","",O10*(1-Settings!$B$4)-K10) | Q10: =IF(OR(O10="",O10=0),"",P10/O10) | S10: =IF(OR(B10="",R10="Paid",R10="Lost",R10="Shipped"),"",B10+Settings!$B$8) | T10: =IF(OR(B10="",R10="Paid",R10="Lost"),"",TODAY()-B10)
A11: =IF(B11="","","Q-"&TEXT(ROW()-4,"000")) | K11: =IF(OR(F11="",I11=""),"",F11*I11+N(J11)) | L11: =IF(K11="","",INDEX(Settings!$B$14:$B$18,MATCH(K11,Settings!$A$14:$A$18,1))) | M11: =IF(K11="","",CEILING(MAX(K11*(1+L11),K11+Settings!$B$5)/(1-Settings!$B$4),Settings!$B$6)) | O11: =IF(K11="","",IF(N11="",M11,N11)) | P11: =IF(O11="","",O11*(1-Settings!$B$4)-K11) | Q11: =IF(OR(O11="",O11=0),"",P11/O11) | S11: =IF(OR(B11="",R11="Paid",R11="Lost",R11="Shipped"),"",B11+Settings!$B$8) | T11: =IF(OR(B11="",R11="Paid",R11="Lost"),"",TODAY()-B11)
A12: =IF(B12="","","Q-"&TEXT(ROW()-4,"000")) | K12: =IF(OR(F12="",I12=""),"",F12*I12+N(J12)) | L12: =IF(K12="","",INDEX(Settings!$B$14:$B$18,MATCH(K12,Settings!$A$14:$A$18,1))) | M12: =IF(K12="","",CEILING(MAX(K12*(1+L12),K12+Settings!$B$5)/(1-Settings!$B$4),Settings!$B$6)) | O12: =IF(K12="","",IF(N12="",M12,N12)) | P12: =IF(O12="","",O12*(1-Settings!$B$4)-K12) | Q12: =IF(OR(O12="",O12=0),"",P12/O12) | S12: =IF(OR(B12="",R12="Paid",R12="Lost",R12="Shipped"),"",B12+Settings!$B$8) | T12: =IF(OR(B12="",R12="Paid",R12="Lost"),"",TODAY()-B12)
A13: =IF(B13="","","Q-"&TEXT(ROW()-4,"000")) | K13: =IF(OR(F13="",I13=""),"",F13*I13+N(J13)) | L13: =IF(K13="","",INDEX(Settings!$B$14:$B$18,MATCH(K13,Settings!$A$14:$A$18,1))) | M13: =IF(K13="","",CEILING(MAX(K13*(1+L13),K13+Settings!$B$5)/(1-Settings!$B$4),Settings!$B$6)) | O13: =IF(K13="","",IF(N13="",M13,N13)) | P13: =IF(O13="","",O13*(1-Settings!$B$4)-K13) | Q13: =IF(OR(O13="",O13=0),"",P13/O13) | S13: =IF(OR(B13="",R13="Paid",R13="Lost",R13="Shipped"),"",B13+Settings!$B$8) | T13: =IF(OR(B13="",R13="Paid",R13="Lost"),"",TODAY()-B13)
A14: =IF(B14="","","Q-"&TEXT(ROW()-4,"000")) | K14: =IF(OR(F14="",I14=""),"",F14*I14+N(J14)) | L14: =IF(K14="","",INDEX(Settings!$B$14:$B$18,MATCH(K14,Settings!$A$14:$A$18,1))) | M14: =IF(K14="","",CEILING(MAX(K14*(1+L14),K14+Settings!$B$5)/(1-Settings!$B$4),Settings!$B$6)) | O14: =IF(K14="","",IF(N14="",M14,N14)) | P14: =IF(O14="","",O14*(1-Settings!$B$4)-K14) | Q14: =IF(OR(O14="",O14=0),"",P14/O14) | S14: =IF(OR(B14="",R14="Paid",R14="Lost",R14="Shipped"),"",B14+Settings!$B$8) | T14: =IF(OR(B14="",R14="Paid",R14="Lost"),"",TODAY()-B14)
A15: =IF(B15="","","Q-"&TEXT(ROW()-4,"000")) | K15: =IF(OR(F15="",I15=""),"",F15*I15+N(J15)) | L15: =IF(K15="","",INDEX(Settings!$B$14:$B$18,MATCH(K15,Settings!$A$14:$A$18,1))) | M15: =IF(K15="","",CEILING(MAX(K15*(1+L15),K15+Settings!$B$5)/(1-Settings!$B$4),Settings!$B$6)) | O15: =IF(K15="","",IF(N15="",M15,N15)) | P15: =IF(O15="","",O15*(1-Settings!$B$4)-K15) | Q15: =IF(OR(O15="",O15=0),"",P15/O15) | S15: =IF(OR(B15="",R15="Paid",R15="Lost",R15="Shipped"),"",B15+Settings!$B$8) | T15: =IF(OR(B15="",R15="Paid",R15="Lost"),"",TODAY()-B15)
A16: =IF(B16="","","Q-"&TEXT(ROW()-4,"000")) | K16: =IF(OR(F16="",I16=""),"",F16*I16+N(J16)) | L16: =IF(K16="","",INDEX(Settings!$B$14:$B$18,MATCH(K16,Settings!$A$14:$A$18,1))) | M16: =IF(K16="","",CEILING(MAX(K16*(1+L16),K16+Settings!$B$5)/(1-Settings!$B$4),Settings!$B$6)) | O16: =IF(K16="","",IF(N16="",M16,N16)) | P16: =IF(O16="","",O16*(1-Settings!$B$4)-K16) | Q16: =IF(OR(O16="",O16=0),"",P16/O16) | S16: =IF(OR(B16="",R16="Paid",R16="Lost",R16="Shipped"),"",B16+Settings!$B$8) | T16: =IF(OR(B16="",R16="Paid",R16="Lost"),"",TODAY()-B16)
A17: =IF(B17="","","Q-"&TEXT(ROW()-4,"000")) | K17: =IF(OR(F17="",I17=""),"",F17*I17+N(J17)) | L17: =IF(K17="","",INDEX(Settings!$B$14:$B$18,MATCH(K17,Settings!$A$14:$A$18,1))) | M17: =IF(K17="","",CEILING(MAX(K17*(1+L17),K17+Settings!$B$5)/(1-Settings!$B$4),Settings!$B$6)) | O17: =IF(K17="","",IF(N17="",M17,N17)) | P17: =IF(O17="","",O17*(1-Settings!$B$4)-K17) | Q17: =IF(OR(O17="",O17=0),"",P17/O17) | S17: =IF(OR(B17="",R17="Paid",R17="Lost",R17="Shipped"),"",B17+Settings!$B$8) | T17: =IF(OR(B17="",R17="Paid",R17="Lost"),"",TODAY()-B17)
A18: =IF(B18="","","Q-"&TEXT(ROW()-4,"000")) | K18: =IF(OR(F18="",I18=""),"",F18*I18+N(J18)) | L18: =IF(K18="","",INDEX(Settings!$B$14:$B$18,MATCH(K18,Settings!$A$14:$A$18,1))) | M18: =IF(K18="","",CEILING(MAX(K18*(1+L18),K18+Settings!$B$5)/(1-Settings!$B$4),Settings!$B$6)) | O18: =IF(K18="","",IF(N18="",M18,N18)) | P18: =IF(O18="","",O18*(1-Settings!$B$4)-K18) | Q18: =IF(OR(O18="",O18=0),"",P18/O18) | S18: =IF(OR(B18="",R18="Paid",R18="Lost",R18="Shipped"),"",B18+Settings!$B$8) | T18: =IF(OR(B18="",R18="Paid",R18="Lost"),"",TODAY()-B18)
A19: =IF(B19="","","Q-"&TEXT(ROW()-4,"000")) | K19: =IF(OR(F19="",I19=""),"",F19*I19+N(J19)) | L19: =IF(K19="","",INDEX(Settings!$B$14:$B$18,MATCH(K19,Settings!$A$14:$A$18,1))) | M19: =IF(K19="","",CEILING(MAX(K19*(1+L19),K19+Settings!$B$5)/(1-Settings!$B$4),Settings!$B$6)) | O19: =IF(K19="","",IF(N19="",M19,N19)) | P19: =IF(O19="","",O19*(1-Settings!$B$4)-K19) | Q19: =IF(OR(O19="",O19=0),"",P19/O19) | S19: =IF(OR(B19="",R19="Paid",R19="Lost",R19="Shipped"),"",B19+Settings!$B$8) | T19: =IF(OR(B19="",R19="Paid",R19="Lost"),"",TODAY()-B19)
... A304: =IF(B304="","","Q-"&TEXT(ROW()-4,"000")) | K304: =IF(OR(F304="",I304=""),"",F304*I304+N(J304)) | L304: =IF(K304="","",INDEX(Settings!$B$14:$B$18,MATCH(K304,Settings!$A$14:$A$18,1))) | M304: =IF(K304="","",CEILING(MAX(K304*(1+L304),K304+Settings!$B$5)/(1-Settings!$B$4),Settings!$B$6)) | O304: =IF(K304="","",IF(N304="",M304,N304)) | P304: =IF(O304="","",O304*(1-Settings!$B$4)-K304) | Q304: =IF(OR(O304="",O304=0),"",P304/O304) | S304: =IF(OR(B304="",R304="Paid",R304="Lost",R304="Shipped"),"",B304+Settings!$B$8) | T304: =IF(OR(B304="",R304="Paid",R304="Lost"),"",TODAY()-B304)

Sheet Suppliers
A1: Suppliers — the black book
A2: Every source you know. 'Deals' and 'Profit' fill in automatically from RFQ Log.
A4: Supplier | B4: Contact person | C4: Phone | D4: Email | E4: What they carry | F4: Lead time (days) | G4: Payment terms | H4: Min order / notes | I4: Drop-ship? | J4: Rating (1–5) | K4: Deals | L4: Profit through them ($) | M4: Notes
A5: Midwest Bearing Supply (example) | B5: Dana | C5: 555-0100 | D5: sales@example.com | E5: Bearings, seals, belts, PT components | F5: 2 | G5: Net 30 after 1st order | H5: $50 min | I5: Yes | J5: 5 | K5: =IF(A5="","",COUNTIF('RFQ Log'!$H$5:$H$304,A5)) -> 2 | L5: =IF(A5="","",SUMIFS('RFQ Log'!$P$5:$P$304,'RFQ Log'!$H$5:$H$304,A5,'RFQ Log'!$R$5:$R$304,"Paid")) -> 52.05 | M5: Fast, ask for counter price
A6: Great Lakes Industrial (example) | B6: Sam | C6: 555-0144 | D6: quotes@example.com | E6: Drives, motors, controls | F6: 5 | G6: Prepay | H6: None | I6: Yes | J6: 4 | K6: =IF(A6="","",COUNTIF('RFQ Log'!$H$5:$H$304,A6)) -> 1 | L6: =IF(A6="","",SUMIFS('RFQ Log'!$P$5:$P$304,'RFQ Log'!$H$5:$H$304,A6,'RFQ Log'!$R$5:$R$304,"Paid")) -> 0 | M6: Call, don't email
K7: =IF(A7="","",COUNTIF('RFQ Log'!$H$5:$H$304,A7)) | L7: =IF(A7="","",SUMIFS('RFQ Log'!$P$5:$P$304,'RFQ Log'!$H$5:$H$304,A7,'RFQ Log'!$R$5:$R$304,"Paid"))
K8: =IF(A8="","",COUNTIF('RFQ Log'!$H$5:$H$304,A8)) | L8: =IF(A8="","",SUMIFS('RFQ Log'!$P$5:$P$304,'RFQ Log'!$H$5:$H$304,A8,'RFQ Log'!$R$5:$R$304,"Paid"))
K9: =IF(A9="","",COUNTIF('RFQ Log'!$H$5:$H$304,A9)) | L9: =IF(A9="","",SUMIFS('RFQ Log'!$P$5:$P$304,'RFQ Log'!$H$5:$H$304,A9,'RFQ Log'!$R$5:$R$304,"Paid"))
K10: =IF(A10="","",COUNTIF('RFQ Log'!$H$5:$H$304,A10)) | L10: =IF(A10="","",SUMIFS('RFQ Log'!$P$5:$P$304,'RFQ Log'!$H$5:$H$304,A10,'RFQ Log'!$R$5:$R$304,"Paid"))
K11: =IF(A11="","",COUNTIF('RFQ Log'!$H$5:$H$304,A11)) | L11: =IF(A11="","",SUMIFS('RFQ Log'!$P$5:$P$304,'RFQ Log'!$H$5:$H$304,A11,'RFQ Log'!$R$5:$R$304,"Paid"))
K12: =IF(A12="","",COUNTIF('RFQ Log'!$H$5:$H$304,A12)) | L12: =IF(A12="","",SUMIFS('RFQ Log'!$P$5:$P$304,'RFQ Log'!$H$5:$H$304,A12,'RFQ Log'!$R$5:$R$304,"Paid"))
K13: =IF(A13="","",COUNTIF('RFQ Log'!$H$5:$H$304,A13)) | L13: =IF(A13="","",SUMIFS('RFQ Log'!$P$5:$P$304,'RFQ Log'!$H$5:$H$304,A13,'RFQ Log'!$R$5:$R$304,"Paid"))
K14: =IF(A14="","",COUNTIF('RFQ Log'!$H$5:$H$304,A14)) | L14: =IF(A14="","",SUMIFS('RFQ Log'!$P$5:$P$304,'RFQ Log'!$H$5:$H$304,A14,'RFQ Log'!$R$5:$R$304,"Paid"))
K15: =IF(A15="","",COUNTIF('RFQ Log'!$H$5:$H$304,A15)) | L15: =IF(A15="","",SUMIFS('RFQ Log'!$P$5:$P$304,'RFQ Log'!$H$5:$H$304,A15,'RFQ Log'!$R$5:$R$304,"Paid"))
K16: =IF(A16="","",COUNTIF('RFQ Log'!$H$5:$H$304,A16)) | L16: =IF(A16="","",SUMIFS('RFQ Log'!$P$5:$P$304,'RFQ Log'!$H$5:$H$304,A16,'RFQ Log'!$R$5:$R$304,"Paid"))
K17: =IF(A17="","",COUNTIF('RFQ Log'!$H$5:$H$304,A17)) | L17: =IF(A17="","",SUMIFS('RFQ Log'!$P$5:$P$304,'RFQ Log'!$H$5:$H$304,A17,'RFQ Log'!$R$5:$R$304,"Paid"))
K18: =IF(A18="","",COUNTIF('RFQ Log'!$H$5:$H$304,A18)) | L18: =IF(A18="","",SUMIFS('RFQ Log'!$P$5:$P$304,'RFQ Log'!$H$5:$H$304,A18,'RFQ Log'!$R$5:$R$304,"Paid"))
... K154: =IF(A154="","",COUNTIF('RFQ Log'!$H$5:$H$304,A154)) | L154: =IF(A154="","",SUMIFS('RFQ Log'!$P$5:$P$304,'RFQ Log'!$H$5:$H$304,A154,'RFQ Log'!$R$5:$R$304,"Paid"))

Sheet Customers
A1: Customers — who needs parts
A2: Name must match exactly what you pick in RFQ Log. Totals fill in automatically.
A4: Customer / Company | B4: Contact person | C4: Phone | D4: Email | E4: How they found you | F4: Payment terms you give | G4: Requests | H4: Won | I4: Win rate | J4: Revenue paid ($) | K4: Profit paid ($) | L4: Notes
A5: Acme Fabrication (example) | B5: Jordan | C5: 555-0199 | D5: buyer@example.com | E5: Referral | F5: 50% deposit | G5: =IF(A5="","",COUNTIF('RFQ Log'!$C$5:$C$304,A5)) -> 2 | H5: =IF(A5="","",COUNTIFS('RFQ Log'!$C$5:$C$304,A5,'RFQ Log'!$R$5:$R$304,"Won")+COUNTIFS('RFQ Log'!$C$5:$C$304,A5,'RFQ Log'!$R$5:$R$304,"Ordered")+COUNTIFS('RFQ Log'!$C$5:$C$304,A5,'RFQ Log'!$R$5:$R$304,"Shipped")+COUNTIFS('RFQ Log'!$C$5:$C$304,A5,'RFQ Log'!$R$5:$R$304,"Paid")) -> 1 | I5: =IF(OR(A5="",G5=0),"",H5/G5) -> 0.5 | J5: =IF(A5="","",SUMIFS('RFQ Log'!$O$5:$O$304,'RFQ Log'!$C$5:$C$304,A5,'RFQ Log'!$R$5:$R$304,"Paid")) -> 125 | K5: =IF(A5="","",SUMIFS('RFQ Log'!$P$5:$P$304,'RFQ Log'!$C$5:$C$304,A5,'RFQ Log'!$R$5:$R$304,"Paid")) -> 52.05 | L5: Maintenance mgr; orders bearings monthly
A6: Lakeside Machine Shop (example) | B6: Chris | C6: 555-0123 | D6: office@example.com | E6: Word of mouth | F6: Prepay | G6: =IF(A6="","",COUNTIF('RFQ Log'!$C$5:$C$304,A6)) -> 1 | H6: =IF(A6="","",COUNTIFS('RFQ Log'!$C$5:$C$304,A6,'RFQ Log'!$R$5:$R$304,"Won")+COUNTIFS('RFQ Log'!$C$5:$C$304,A6,'RFQ Log'!$R$5:$R$304,"Ordered")+COUNTIFS('RFQ Log'!$C$5:$C$304,A6,'RFQ Log'!$R$5:$R$304,"Shipped")+COUNTIFS('RFQ Log'!$C$5:$C$304,A6,'RFQ Log'!$R$5:$R$304,"Paid")) -> 1 | I6: =IF(OR(A6="",G6=0),"",H6/G6) -> 1 | J6: =IF(A6="","",SUMIFS('RFQ Log'!$O$5:$O$304,'RFQ Log'!$C$5:$C$304,A6,'RFQ Log'!$R$5:$R$304,"Paid")) -> 0 | K6: =IF(A6="","",SUMIFS('RFQ Log'!$P$5:$P$304,'RFQ Log'!$C$5:$C$304,A6,'RFQ Log'!$R$5:$R$304,"Paid")) -> 0 | L6: Downtime-driven — pays for speed
G7: =IF(A7="","",COUNTIF('RFQ Log'!$C$5:$C$304,A7)) | H7: =IF(A7="","",COUNTIFS('RFQ Log'!$C$5:$C$304,A7,'RFQ Log'!$R$5:$R$304,"Won")+COUNTIFS('RFQ Log'!$C$5:$C$304,A7,'RFQ Log'!$R$5:$R$304,"Ordered")+COUNTIFS('RFQ Log'!$C$5:$C$304,A7,'RFQ Log'!$R$5:$R$304,"Shipped")+COUNTIFS('RFQ Log'!$C$5:$C$304,A7,'RFQ Log'!$R$5:$R$304,"Paid")) | I7: =IF(OR(A7="",G7=0),"",H7/G7) | J7: =IF(A7="","",SUMIFS('RFQ Log'!$O$5:$O$304,'RFQ Log'!$C$5:$C$304,A7,'RFQ Log'!$R$5:$R$304,"Paid")) | K7: =IF(A7="","",SUMIFS('RFQ Log'!$P$5:$P$304,'RFQ Log'!$C$5:$C$304,A7,'RFQ Log'!$R$5:$R$304,"Paid"))
G8: =IF(A8="","",COUNTIF('RFQ Log'!$C$5:$C$304,A8)) | H8: =IF(A8="","",COUNTIFS('RFQ Log'!$C$5:$C$304,A8,'RFQ Log'!$R$5:$R$304,"Won")+COUNTIFS('RFQ Log'!$C$5:$C$304,A8,'RFQ Log'!$R$5:$R$304,"Ordered")+COUNTIFS('RFQ Log'!$C$5:$C$304,A8,'RFQ Log'!$R$5:$R$304,"Shipped")+COUNTIFS('RFQ Log'!$C$5:$C$304,A8,'RFQ Log'!$R$5:$R$304,"Paid")) | I8: =IF(OR(A8="",G8=0),"",H8/G8) | J8: =IF(A8="","",SUMIFS('RFQ Log'!$O$5:$O$304,'RFQ Log'!$C$5:$C$304,A8,'RFQ Log'!$R$5:$R$304,"Paid")) | K8: =IF(A8="","",SUMIFS('RFQ Log'!$P$5:$P$304,'RFQ Log'!$C$5:$C$304,A8,'RFQ Log'!$R$5:$R$304,"Paid"))
G9: =IF(A9="","",COUNTIF('RFQ Log'!$C$5:$C$304,A9)) | H9: =IF(A9="","",COUNTIFS('RFQ Log'!$C$5:$C$304,A9,'RFQ Log'!$R$5:$R$304,"Won")+COUNTIFS('RFQ Log'!$C$5:$C$304,A9,'RFQ Log'!$R$5:$R$304,"Ordered")+COUNTIFS('RFQ Log'!$C$5:$C$304,A9,'RFQ Log'!$R$5:$R$304,"Shipped")+COUNTIFS('RFQ Log'!$C$5:$C$304,A9,'RFQ Log'!$R$5:$R$304,"Paid")) | I9: =IF(OR(A9="",G9=0),"",H9/G9) | J9: =IF(A9="","",SUMIFS('RFQ Log'!$O$5:$O$304,'RFQ Log'!$C$5:$C$304,A9,'RFQ Log'!$R$5:$R$304,"Paid")) | K9: =IF(A9="","",SUMIFS('RFQ Log'!$P$5:$P$304,'RFQ Log'!$C$5:$C$304,A9,'RFQ Log'!$R$5:$R$304,"Paid"))
G10: =IF(A10="","",COUNTIF('RFQ Log'!$C$5:$C$304,A10)) | H10: =IF(A10="","",COUNTIFS('RFQ Log'!$C$5:$C$304,A10,'RFQ Log'!$R$5:$R$304,"Won")+COUNTIFS('RFQ Log'!$C$5:$C$304,A10,'RFQ Log'!$R$5:$R$304,"Ordered")+COUNTIFS('RFQ Log'!$C$5:$C$304,A10,'RFQ Log'!$R$5:$R$304,"Shipped")+COUNTIFS('RFQ Log'!$C$5:$C$304,A10,'RFQ Log'!$R$5:$R$304,"Paid")) | I10: =IF(OR(A10="",G10=0),"",H10/G10) | J10: =IF(A10="","",SUMIFS('RFQ Log'!$O$5:$O$304,'RFQ Log'!$C$5:$C$304,A10,'RFQ Log'!$R$5:$R$304,"Paid")) | K10: =IF(A10="","",SUMIFS('RFQ Log'!$P$5:$P$304,'RFQ Log'!$C$5:$C$304,A10,'RFQ Log'!$R$5:$R$304,"Paid"))
G11: =IF(A11="","",COUNTIF('RFQ Log'!$C$5:$C$304,A11)) | H11: =IF(A11="","",COUNTIFS('RFQ Log'!$C$5:$C$304,A11,'RFQ Log'!$R$5:$R$304,"Won")+COUNTIFS('RFQ Log'!$C$5:$C$304,A11,'RFQ Log'!$R$5:$R$304,"Ordered")+COUNTIFS('RFQ Log'!$C$5:$C$304,A11,'RFQ Log'!$R$5:$R$304,"Shipped")+COUNTIFS('RFQ Log'!$C$5:$C$304,A11,'RFQ Log'!$R$5:$R$304,"Paid")) | I11: =IF(OR(A11="",G11=0),"",H11/G11) | J11: =IF(A11="","",SUMIFS('RFQ Log'!$O$5:$O$304,'RFQ Log'!$C$5:$C$304,A11,'RFQ Log'!$R$5:$R$304,"Paid")) | K11: =IF(A11="","",SUMIFS('RFQ Log'!$P$5:$P$304,'RFQ Log'!$C$5:$C$304,A11,'RFQ Log'!$R$5:$R$304,"Paid"))
G12: =IF(A12="","",COUNTIF('RFQ Log'!$C$5:$C$304,A12)) | H12: =IF(A12="","",COUNTIFS('RFQ Log'!$C$5:$C$304,A12,'RFQ Log'!$R$5:$R$304,"Won")+COUNTIFS('RFQ Log'!$C$5:$C$304,A12,'RFQ Log'!$R$5:$R$304,"Ordered")+COUNTIFS('RFQ Log'!$C$5:$C$304,A12,'RFQ Log'!$R$5:$R$304,"Shipped")+COUNTIFS('RFQ Log'!$C$5:$C$304,A12,'RFQ Log'!$R$5:$R$304,"Paid")) | I12: =IF(OR(A12="",G12=0),"",H12/G12) | J12: =IF(A12="","",SUMIFS('RFQ Log'!$O$5:$O$304,'RFQ Log'!$C$5:$C$304,A12,'RFQ Log'!$R$5:$R$304,"Paid")) | K12: =IF(A12="","",SUMIFS('RFQ Log'!$P$5:$P$304,'RFQ Log'!$C$5:$C$304,A12,'RFQ Log'!$R$5:$R$304,"Paid"))
G13: =IF(A13="","",COUNTIF('RFQ Log'!$C$5:$C$304,A13)) | H13: =IF(A13="","",COUNTIFS('RFQ Log'!$C$5:$C$304,A13,'RFQ Log'!$R$5:$R$304,"Won")+COUNTIFS('RFQ Log'!$C$5:$C$304,A13,'RFQ Log'!$R$5:$R$304,"Ordered")+COUNTIFS('RFQ Log'!$C$5:$C$304,A13,'RFQ Log'!$R$5:$R$304,"Shipped")+COUNTIFS('RFQ Log'!$C$5:$C$304,A13,'RFQ Log'!$R$5:$R$304,"Paid")) | I13: =IF(OR(A13="",G13=0),"",H13/G13) | J13: =IF(A13="","",SUMIFS('RFQ Log'!$O$5:$O$304,'RFQ Log'!$C$5:$C$304,A13,'RFQ Log'!$R$5:$R$304,"Paid")) | K13: =IF(A13="","",SUMIFS('RFQ Log'!$P$5:$P$304,'RFQ Log'!$C$5:$C$304,A13,'RFQ Log'!$R$5:$R$304,"Paid"))
G14: =IF(A14="","",COUNTIF('RFQ Log'!$C$5:$C$304,A14)) | H14: =IF(A14="","",COUNTIFS('RFQ Log'!$C$5:$C$304,A14,'RFQ Log'!$R$5:$R$304,"Won")+COUNTIFS('RFQ Log'!$C$5:$C$304,A14,'RFQ Log'!$R$5:$R$304,"Ordered")+COUNTIFS('RFQ Log'!$C$5:$C$304,A14,'RFQ Log'!$R$5:$R$304,"Shipped")+COUNTIFS('RFQ Log'!$C$5:$C$304,A14,'RFQ Log'!$R$5:$R$304,"Paid")) | I14: =IF(OR(A14="",G14=0),"",H14/G14) | J14: =IF(A14="","",SUMIFS('RFQ Log'!$O$5:$O$304,'RFQ Log'!$C$5:$C$304,A14,'RFQ Log'!$R$5:$R$304,"Paid")) | K14: =IF(A14="","",SUMIFS('RFQ Log'!$P$5:$P$304,'RFQ Log'!$C$5:$C$304,A14,'RFQ Log'!$R$5:$R$304,"Paid"))
G15: =IF(A15="","",COUNTIF('RFQ Log'!$C$5:$C$304,A15)) | H15: =IF(A15="","",COUNTIFS('RFQ Log'!$C$5:$C$304,A15,'RFQ Log'!$R$5:$R$304,"Won")+COUNTIFS('RFQ Log'!$C$5:$C$304,A15,'RFQ Log'!$R$5:$R$304,"Ordered")+COUNTIFS('RFQ Log'!$C$5:$C$304,A15,'RFQ Log'!$R$5:$R$304,"Shipped")+COUNTIFS('RFQ Log'!$C$5:$C$304,A15,'RFQ Log'!$R$5:$R$304,"Paid")) | I15: =IF(OR(A15="",G15=0),"",H15/G15) | J15: =IF(A15="","",SUMIFS('RFQ Log'!$O$5:$O$304,'RFQ Log'!$C$5:$C$304,A15,'RFQ Log'!$R$5:$R$304,"Paid")) | K15: =IF(A15="","",SUMIFS('RFQ Log'!$P$5:$P$304,'RFQ Log'!$C$5:$C$304,A15,'RFQ Log'!$R$5:$R$304,"Paid"))
G16: =IF(A16="","",COUNTIF('RFQ Log'!$C$5:$C$304,A16)) | H16: =IF(A16="","",COUNTIFS('RFQ Log'!$C$5:$C$304,A16,'RFQ Log'!$R$5:$R$304,"Won")+COUNTIFS('RFQ Log'!$C$5:$C$304,A16,'RFQ Log'!$R$5:$R$304,"Ordered")+COUNTIFS('RFQ Log'!$C$5:$C$304,A16,'RFQ Log'!$R$5:$R$304,"Shipped")+COUNTIFS('RFQ Log'!$C$5:$C$304,A16,'RFQ Log'!$R$5:$R$304,"Paid")) | I16: =IF(OR(A16="",G16=0),"",H16/G16) | J16: =IF(A16="","",SUMIFS('RFQ Log'!$O$5:$O$304,'RFQ Log'!$C$5:$C$304,A16,'RFQ Log'!$R$5:$R$304,"Paid")) | K16: =IF(A16="","",SUMIFS('RFQ Log'!$P$5:$P$304,'RFQ Log'!$C$5:$C$304,A16,'RFQ Log'!$R$5:$R$304,"Paid"))
G17: =IF(A17="","",COUNTIF('RFQ Log'!$C$5:$C$304,A17)) | H17: =IF(A17="","",COUNTIFS('RFQ Log'!$C$5:$C$304,A17,'RFQ Log'!$R$5:$R$304,"Won")+COUNTIFS('RFQ Log'!$C$5:$C$304,A17,'RFQ Log'!$R$5:$R$304,"Ordered")+COUNTIFS('RFQ Log'!$C$5:$C$304,A17,'RFQ Log'!$R$5:$R$304,"Shipped")+COUNTIFS('RFQ Log'!$C$5:$C$304,A17,'RFQ Log'!$R$5:$R$304,"Paid")) | I17: =IF(OR(A17="",G17=0),"",H17/G17) | J17: =IF(A17="","",SUMIFS('RFQ Log'!$O$5:$O$304,'RFQ Log'!$C$5:$C$304,A17,'RFQ Log'!$R$5:$R$304,"Paid")) | K17: =IF(A17="","",SUMIFS('RFQ Log'!$P$5:$P$304,'RFQ Log'!$C$5:$C$304,A17,'RFQ Log'!$R$5:$R$304,"Paid"))
G18: =IF(A18="","",COUNTIF('RFQ Log'!$C$5:$C$304,A18)) | H18: =IF(A18="","",COUNTIFS('RFQ Log'!$C$5:$C$304,A18,'RFQ Log'!$R$5:$R$304,"Won")+COUNTIFS('RFQ Log'!$C$5:$C$304,A18,'RFQ Log'!$R$5:$R$304,"Ordered")+COUNTIFS('RFQ Log'!$C$5:$C$304,A18,'RFQ Log'!$R$5:$R$304,"Shipped")+COUNTIFS('RFQ Log'!$C$5:$C$304,A18,'RFQ Log'!$R$5:$R$304,"Paid")) | I18: =IF(OR(A18="",G18=0),"",H18/G18) | J18: =IF(A18="","",SUMIFS('RFQ Log'!$O$5:$O$304,'RFQ Log'!$C$5:$C$304,A18,'RFQ Log'!$R$5:$R$304,"Paid")) | K18: =IF(A18="","",SUMIFS('RFQ Log'!$P$5:$P$304,'RFQ Log'!$C$5:$C$304,A18,'RFQ Log'!$R$5:$R$304,"Paid"))
... G154: =IF(A154="","",COUNTIF('RFQ Log'!$C$5:$C$304,A154)) | H154: =IF(A154="","",COUNTIFS('RFQ Log'!$C$5:$C$304,A154,'RFQ Log'!$R$5:$R$304,"Won")+COUNTIFS('RFQ Log'!$C$5:$C$304,A154,'RFQ Log'!$R$5:$R$304,"Ordered")+COUNTIFS('RFQ Log'!$C$5:$C$304,A154,'RFQ Log'!$R$5:$R$304,"Shipped")+COUNTIFS('RFQ Log'!$C$5:$C$304,A154,'RFQ Log'!$R$5:$R$304,"Paid")) | I154: =IF(OR(A154="",G154=0),"",H154/G154) | J154: =IF(A154="","",SUMIFS('RFQ Log'!$O$5:$O$304,'RFQ Log'!$C$5:$C$304,A154,'RFQ Log'!$R$5:$R$304,"Paid")) | K154: =IF(A154="","",SUMIFS('RFQ Log'!$P$5:$P$304,'RFQ Log'!$C$5:$C$304,A154,'RFQ Log'!$R$5:$R$304,"Paid"))
